2018-04-11 15:05:34.441 +02:00 [Information] AuthenticationScheme: "OAuth2Introspection" was successfully authenticated.
2018-04-11 15:05:35.410 +02:00 [Error] 999 : "Failure", "an error occured" : "(null)"
SimpleIdentityServer.Manager.Core.Exceptions.IdentityServerManagerException: the client '.search' doesn't exist
   at SimpleIdentityServer.Manager.Core.Api.Clients.Actions.GetClientAction.<Execute>d__2.MoveNext()
--- End of stack trace from previous location where exception was thrown ---
   at System.Runtime.CompilerServices.TaskAwaiter.ThrowForNonSuccess(Task task)
   at System.Runtime.CompilerServices.TaskAwaiter.HandleNonSuccessAndDebuggerNotification(Task task)
   at System.Runtime.CompilerServices.TaskAwaiter`1.GetResult()
   at SimpleIdentityServer.Manager.Host.Controllers.ClientsController.<Get>d__7.MoveNext()
--- End of stack trace from previous location where exception was thrown ---
   at System.Runtime.CompilerServices.TaskAwaiter.ThrowForNonSuccess(Task task)
   at System.Runtime.CompilerServices.TaskAwaiter.HandleNonSuccessAndDebuggerNotification(Task task)
   at lambda_method(Closure , Object )
   at Microsoft.Extensions.Internal.ObjectMethodExecutorAwaitable.Awaiter.GetResult()
   at Microsoft.AspNetCore.Mvc.Internal.ControllerActionInvoker.<InvokeActionMethodAsync>d__12.MoveNext()
--- End of stack trace from previous location where exception was thrown ---
   at System.Runtime.CompilerServices.TaskAwaiter.ThrowForNonSuccess(Task task)
   at System.Runtime.CompilerServices.TaskAwaiter.HandleNonSuccessAndDebuggerNotification(Task task)
   at Microsoft.AspNetCore.Mvc.Internal.ControllerActionInvoker.<InvokeNextActionFilterAsync>d__10.MoveNext()
--- End of stack trace from previous location where exception was thrown ---
   at Microsoft.AspNetCore.Mvc.Internal.ControllerActionInvoker.Rethrow(ActionExecutedContext context)
   at Microsoft.AspNetCore.Mvc.Internal.ControllerActionInvoker.Next(State& next, Scope& scope, Object& state, Boolean& isCompleted)
   at Microsoft.AspNetCore.Mvc.Internal.ControllerActionInvoker.<InvokeInnerFilterAsync>d__14.MoveNext()
--- End of stack trace from previous location where exception was thrown ---
   at System.Runtime.CompilerServices.TaskAwaiter.ThrowForNonSuccess(Task task)
   at System.Runtime.CompilerServices.TaskAwaiter.HandleNonSuccessAndDebuggerNotification(Task task)
   at Microsoft.AspNetCore.Mvc.Internal.ResourceInvoker.<InvokeNextResourceFilter>d__22.MoveNext()
--- End of stack trace from previous location where exception was thrown ---
   at Microsoft.AspNetCore.Mvc.Internal.ResourceInvoker.Rethrow(ResourceExecutedContext context)
   at Microsoft.AspNetCore.Mvc.Internal.ResourceInvoker.Next(State& next, Scope& scope, Object& state, Boolean& isCompleted)
   at Microsoft.AspNetCore.Mvc.Internal.ResourceInvoker.<InvokeFilterPipelineAsync>d__17.MoveNext()
--- End of stack trace from previous location where exception was thrown ---
   at System.Runtime.CompilerServices.TaskAwaiter.ThrowForNonSuccess(Task task)
   at System.Runtime.CompilerServices.TaskAwaiter.HandleNonSuccessAndDebuggerNotification(Task task)
   at Microsoft.AspNetCore.Mvc.Internal.ResourceInvoker.<InvokeAsync>d__15.MoveNext()
--- End of stack trace from previous location where exception was thrown ---
   at System.Runtime.CompilerServices.TaskAwaiter.ThrowForNonSuccess(Task task)
   at System.Runtime.CompilerServices.TaskAwaiter.HandleNonSuccessAndDebuggerNotification(Task task)
   at Microsoft.AspNetCore.Builder.RouterMiddleware.<Invoke>d__4.MoveNext()
--- End of stack trace from previous location where exception was thrown ---
   at System.Runtime.CompilerServices.TaskAwaiter.ThrowForNonSuccess(Task task)
   at System.Runtime.CompilerServices.TaskAwaiter.HandleNonSuccessAndDebuggerNotification(Task task)
   at System.Runtime.CompilerServices.TaskAwaiter.GetResult()
   at SimpleIdentityServer.Manager.Host.Middleware.ExceptionHandlerMiddleware.<Invoke>d__3.MoveNext()
2018-04-11 15:05:45.627 +02:00 [Information] AuthenticationScheme: "OAuth2Introspection" was successfully authenticated.
2018-04-11 15:05:45.836 +02:00 [Error] An exception occurred in the database while iterating the results of a query for context type '"SimpleIdentityServer.DataAccess.SqlServer.SimpleIdentityServerContext"'."
""System.Data.SqlClient.SqlException (0x80131904): The number of rows provided for a FETCH clause must be greater then zero.
   at System.Data.SqlClient.SqlConnection.OnError(SqlException exception, Boolean breakConnection, Action`1 wrapCloseInAction)
   at System.Data.SqlClient.SqlInternalConnection.OnError(SqlException exception, Boolean breakConnection, Action`1 wrapCloseInAction)
   at System.Data.SqlClient.TdsParser.ThrowExceptionAndWarning(TdsParserStateObject stateObj, Boolean callerHasConnectionLock, Boolean asyncClose)
   at System.Data.SqlClient.TdsParser.TryRun(RunBehavior runBehavior, SqlCommand cmdHandler, SqlDataReader dataStream, BulkCopySimpleResultSet bulkCopyHandler, TdsParserStateObject stateObj, Boolean& dataReady)
   at System.Data.SqlClient.SqlDataReader.TryHasMoreRows(Boolean& moreRows)
   at System.Data.SqlClient.SqlDataReader.TryReadInternal(Boolean setTimeout, Boolean& more)
   at System.Data.SqlClient.SqlDataReader.<>c__DisplayClass189_0.<ReadAsync>b__0(Task t)
   at System.Data.SqlClient.SqlDataReader.InvokeRetryable[T](Func`2 moreFunc, TaskCompletionSource`1 source, IDisposable objectToDispose)
--- End of stack trace from previous location where exception was thrown ---
   at System.Runtime.CompilerServices.TaskAwaiter.ThrowForNonSuccess(Task task)
   at System.Runtime.CompilerServices.TaskAwaiter.HandleNonSuccessAndDebuggerNotification(Task task)
   at Microsoft.EntityFrameworkCore.Query.Internal.AsyncQueryingEnumerable`1.AsyncEnumerator.<BufferlessMoveNext>d__10.MoveNext()
--- End of stack trace from previous location where exception was thrown ---
   at System.Runtime.CompilerServices.TaskAwaiter.ThrowForNonSuccess(Task task)
   at System.Runtime.CompilerServices.TaskAwaiter.HandleNonSuccessAndDebuggerNotification(Task task)
   at Microsoft.EntityFrameworkCore.Storage.Internal.SqlServerExecutionStrategy.<ExecuteAsync>d__7`2.MoveNext()
--- End of stack trace from previous location where exception was thrown ---
   at System.Runtime.CompilerServices.TaskAwaiter.ThrowForNonSuccess(Task task)
   at System.Runtime.CompilerServices.TaskAwaiter.HandleNonSuccessAndDebuggerNotification(Task task)
   at Microsoft.EntityFrameworkCore.Query.Internal.AsyncQueryingEnumerable`1.AsyncEnumerator.<MoveNext>d__9.MoveNext()
--- End of stack trace from previous location where exception was thrown ---
   at System.Runtime.CompilerServices.TaskAwaiter.ThrowForNonSuccess(Task task)
   at System.Runtime.CompilerServices.TaskAwaiter.HandleNonSuccessAndDebuggerNotification(Task task)
   at Microsoft.EntityFrameworkCore.Query.Internal.AsyncLinqOperatorProvider.ExceptionInterceptor`1.EnumeratorExceptionInterceptor.<MoveNext>d__5.MoveNext()
ClientConnectionId:ff22119d-c466-4b94-9c03-e00f51c84a3c
Error Number:10744,State:1,Class:15"
System.Data.SqlClient.SqlException (0x80131904): The number of rows provided for a FETCH clause must be greater then zero.
   at System.Data.SqlClient.SqlConnection.OnError(SqlException exception, Boolean breakConnection, Action`1 wrapCloseInAction)
   at System.Data.SqlClient.SqlInternalConnection.OnError(SqlException exception, Boolean breakConnection, Action`1 wrapCloseInAction)
   at System.Data.SqlClient.TdsParser.ThrowExceptionAndWarning(TdsParserStateObject stateObj, Boolean callerHasConnectionLock, Boolean asyncClose)
   at System.Data.SqlClient.TdsParser.TryRun(RunBehavior runBehavior, SqlCommand cmdHandler, SqlDataReader dataStream, BulkCopySimpleResultSet bulkCopyHandler, TdsParserStateObject stateObj, Boolean& dataReady)
   at System.Data.SqlClient.SqlDataReader.TryHasMoreRows(Boolean& moreRows)
   at System.Data.SqlClient.SqlDataReader.TryReadInternal(Boolean setTimeout, Boolean& more)
   at System.Data.SqlClient.SqlDataReader.<>c__DisplayClass189_0.<ReadAsync>b__0(Task t)
   at System.Data.SqlClient.SqlDataReader.InvokeRetryable[T](Func`2 moreFunc, TaskCompletionSource`1 source, IDisposable objectToDispose)
--- End of stack trace from previous location where exception was thrown ---
   at System.Runtime.CompilerServices.TaskAwaiter.ThrowForNonSuccess(Task task)
   at System.Runtime.CompilerServices.TaskAwaiter.HandleNonSuccessAndDebuggerNotification(Task task)
   at Microsoft.EntityFrameworkCore.Query.Internal.AsyncQueryingEnumerable`1.AsyncEnumerator.<BufferlessMoveNext>d__10.MoveNext()
--- End of stack trace from previous location where exception was thrown ---
   at System.Runtime.CompilerServices.TaskAwaiter.ThrowForNonSuccess(Task task)
   at System.Runtime.CompilerServices.TaskAwaiter.HandleNonSuccessAndDebuggerNotification(Task task)
   at Microsoft.EntityFrameworkCore.Storage.Internal.SqlServerExecutionStrategy.<ExecuteAsync>d__7`2.MoveNext()
--- End of stack trace from previous location where exception was thrown ---
   at System.Runtime.CompilerServices.TaskAwaiter.ThrowForNonSuccess(Task task)
   at System.Runtime.CompilerServices.TaskAwaiter.HandleNonSuccessAndDebuggerNotification(Task task)
   at Microsoft.EntityFrameworkCore.Query.Internal.AsyncQueryingEnumerable`1.AsyncEnumerator.<MoveNext>d__9.MoveNext()
--- End of stack trace from previous location where exception was thrown ---
   at System.Runtime.CompilerServices.TaskAwaiter.ThrowForNonSuccess(Task task)
   at System.Runtime.CompilerServices.TaskAwaiter.HandleNonSuccessAndDebuggerNotification(Task task)
   at Microsoft.EntityFrameworkCore.Query.Internal.AsyncLinqOperatorProvider.ExceptionInterceptor`1.EnumeratorExceptionInterceptor.<MoveNext>d__5.MoveNext()
ClientConnectionId:ff22119d-c466-4b94-9c03-e00f51c84a3c
Error Number:10744,State:1,Class:15
2018-04-11 15:05:45.858 +02:00 [Error] 999 : "Failure", "an error occured" : "(null)"
SimpleIdentityServer.Manager.Core.Exceptions.IdentityServerManagerException: The number of rows provided for a FETCH clause must be greater then zero.
2018-04-11 15:06:31.457 +02:00 [Information] AuthenticationScheme: "OAuth2Introspection" was successfully authenticated.
2018-04-11 15:06:31.488 +02:00 [Error] An exception occurred in the database while iterating the results of a query for context type '"SimpleIdentityServer.DataAccess.SqlServer.SimpleIdentityServerContext"'."
""System.Data.SqlClient.SqlException (0x80131904): The number of rows provided for a FETCH clause must be greater then zero.
   at System.Data.SqlClient.SqlConnection.OnError(SqlException exception, Boolean breakConnection, Action`1 wrapCloseInAction)
   at System.Data.SqlClient.SqlInternalConnection.OnError(SqlException exception, Boolean breakConnection, Action`1 wrapCloseInAction)
   at System.Data.SqlClient.TdsParser.ThrowExceptionAndWarning(TdsParserStateObject stateObj, Boolean callerHasConnectionLock, Boolean asyncClose)
   at System.Data.SqlClient.TdsParser.TryRun(RunBehavior runBehavior, SqlCommand cmdHandler, SqlDataReader dataStream, BulkCopySimpleResultSet bulkCopyHandler, TdsParserStateObject stateObj, Boolean& dataReady)
   at System.Data.SqlClient.SqlDataReader.TryHasMoreRows(Boolean& moreRows)
   at System.Data.SqlClient.SqlDataReader.TryReadInternal(Boolean setTimeout, Boolean& more)
   at System.Data.SqlClient.SqlDataReader.<>c__DisplayClass189_0.<ReadAsync>b__0(Task t)
   at System.Data.SqlClient.SqlDataReader.InvokeRetryable[T](Func`2 moreFunc, TaskCompletionSource`1 source, IDisposable objectToDispose)
--- End of stack trace from previous location where exception was thrown ---
   at System.Runtime.CompilerServices.TaskAwaiter.ThrowForNonSuccess(Task task)
   at System.Runtime.CompilerServices.TaskAwaiter.HandleNonSuccessAndDebuggerNotification(Task task)
   at Microsoft.EntityFrameworkCore.Query.Internal.AsyncQueryingEnumerable`1.AsyncEnumerator.<BufferlessMoveNext>d__10.MoveNext()
--- End of stack trace from previous location where exception was thrown ---
   at System.Runtime.CompilerServices.TaskAwaiter.ThrowForNonSuccess(Task task)
   at System.Runtime.CompilerServices.TaskAwaiter.HandleNonSuccessAndDebuggerNotification(Task task)
   at Microsoft.EntityFrameworkCore.Storage.Internal.SqlServerExecutionStrategy.<ExecuteAsync>d__7`2.MoveNext()
--- End of stack trace from previous location where exception was thrown ---
   at System.Runtime.CompilerServices.TaskAwaiter.ThrowForNonSuccess(Task task)
   at System.Runtime.CompilerServices.TaskAwaiter.HandleNonSuccessAndDebuggerNotification(Task task)
   at Microsoft.EntityFrameworkCore.Query.Internal.AsyncQueryingEnumerable`1.AsyncEnumerator.<MoveNext>d__9.MoveNext()
--- End of stack trace from previous location where exception was thrown ---
   at System.Runtime.CompilerServices.TaskAwaiter.ThrowForNonSuccess(Task task)
   at System.Runtime.CompilerServices.TaskAwaiter.HandleNonSuccessAndDebuggerNotification(Task task)
   at Microsoft.EntityFrameworkCore.Query.Internal.AsyncLinqOperatorProvider.ExceptionInterceptor`1.EnumeratorExceptionInterceptor.<MoveNext>d__5.MoveNext()
ClientConnectionId:ff22119d-c466-4b94-9c03-e00f51c84a3c
Error Number:10744,State:1,Class:15"
System.Data.SqlClient.SqlException (0x80131904): The number of rows provided for a FETCH clause must be greater then zero.
   at System.Data.SqlClient.SqlConnection.OnError(SqlException exception, Boolean breakConnection, Action`1 wrapCloseInAction)
   at System.Data.SqlClient.SqlInternalConnection.OnError(SqlException exception, Boolean breakConnection, Action`1 wrapCloseInAction)
   at System.Data.SqlClient.TdsParser.ThrowExceptionAndWarning(TdsParserStateObject stateObj, Boolean callerHasConnectionLock, Boolean asyncClose)
   at System.Data.SqlClient.TdsParser.TryRun(RunBehavior runBehavior, SqlCommand cmdHandler, SqlDataReader dataStream, BulkCopySimpleResultSet bulkCopyHandler, TdsParserStateObject stateObj, Boolean& dataReady)
   at System.Data.SqlClient.SqlDataReader.TryHasMoreRows(Boolean& moreRows)
   at System.Data.SqlClient.SqlDataReader.TryReadInternal(Boolean setTimeout, Boolean& more)
   at System.Data.SqlClient.SqlDataReader.<>c__DisplayClass189_0.<ReadAsync>b__0(Task t)
   at System.Data.SqlClient.SqlDataReader.InvokeRetryable[T](Func`2 moreFunc, TaskCompletionSource`1 source, IDisposable objectToDispose)
--- End of stack trace from previous location where exception was thrown ---
   at System.Runtime.CompilerServices.TaskAwaiter.ThrowForNonSuccess(Task task)
   at System.Runtime.CompilerServices.TaskAwaiter.HandleNonSuccessAndDebuggerNotification(Task task)
   at Microsoft.EntityFrameworkCore.Query.Internal.AsyncQueryingEnumerable`1.AsyncEnumerator.<BufferlessMoveNext>d__10.MoveNext()
--- End of stack trace from previous location where exception was thrown ---
   at System.Runtime.CompilerServices.TaskAwaiter.ThrowForNonSuccess(Task task)
   at System.Runtime.CompilerServices.TaskAwaiter.HandleNonSuccessAndDebuggerNotification(Task task)
   at Microsoft.EntityFrameworkCore.Storage.Internal.SqlServerExecutionStrategy.<ExecuteAsync>d__7`2.MoveNext()
--- End of stack trace from previous location where exception was thrown ---
   at System.Runtime.CompilerServices.TaskAwaiter.ThrowForNonSuccess(Task task)
   at System.Runtime.CompilerServices.TaskAwaiter.HandleNonSuccessAndDebuggerNotification(Task task)
   at Microsoft.EntityFrameworkCore.Query.Internal.AsyncQueryingEnumerable`1.AsyncEnumerator.<MoveNext>d__9.MoveNext()
--- End of stack trace from previous location where exception was thrown ---
   at System.Runtime.CompilerServices.TaskAwaiter.ThrowForNonSuccess(Task task)
   at System.Runtime.CompilerServices.TaskAwaiter.HandleNonSuccessAndDebuggerNotification(Task task)
   at Microsoft.EntityFrameworkCore.Query.Internal.AsyncLinqOperatorProvider.ExceptionInterceptor`1.EnumeratorExceptionInterceptor.<MoveNext>d__5.MoveNext()
ClientConnectionId:ff22119d-c466-4b94-9c03-e00f51c84a3c
Error Number:10744,State:1,Class:15
2018-04-11 15:06:31.518 +02:00 [Error] 999 : "Failure", "an error occured" : "(null)"
SimpleIdentityServer.Manager.Core.Exceptions.IdentityServerManagerException: The number of rows provided for a FETCH clause must be greater then zero.
2018-04-11 15:23:43.461 +02:00 [Information] AuthenticationScheme: "OAuth2Introspection" was successfully authenticated.
2018-04-11 15:25:26.565 +02:00 [Information] AuthenticationScheme: "OAuth2Introspection" was successfully authenticated.
2018-04-11 15:29:01.311 +02:00 [Information] AuthenticationScheme: "OAuth2Introspection" was successfully authenticated.
2018-04-11 15:29:34.223 +02:00 [Information] AuthenticationScheme: "OAuth2Introspection" was successfully authenticated.
2018-04-11 15:30:05.882 +02:00 [Information] AuthenticationScheme: "OAuth2Introspection" was successfully authenticated.
2018-04-11 15:31:38.063 +02:00 [Information] AuthenticationScheme: "OAuth2Introspection" was successfully authenticated.
2018-04-11 15:32:26.881 +02:00 [Information] AuthenticationScheme: "OAuth2Introspection" was successfully authenticated.
2018-04-11 15:33:24.264 +02:00 [Information] AuthenticationScheme: "OAuth2Introspection" was successfully authenticated.
2018-04-11 15:33:54.019 +02:00 [Information] AuthenticationScheme: "OAuth2Introspection" was successfully authenticated.
2018-04-11 15:35:05.873 +02:00 [Information] AuthenticationScheme: "OAuth2Introspection" was successfully authenticated.
2018-04-11 15:35:14.665 +02:00 [Information] AuthenticationScheme: "OAuth2Introspection" was successfully authenticated.
2018-04-11 15:35:16.083 +02:00 [Information] AuthenticationScheme: "OAuth2Introspection" was successfully authenticated.
2018-04-11 15:35:16.974 +02:00 [Information] AuthenticationScheme: "OAuth2Introspection" was successfully authenticated.
2018-04-11 15:35:18.982 +02:00 [Information] AuthenticationScheme: "OAuth2Introspection" was successfully authenticated.
2018-04-11 15:35:20.547 +02:00 [Information] AuthenticationScheme: "OAuth2Introspection" was successfully authenticated.
2018-04-11 15:35:21.706 +02:00 [Information] AuthenticationScheme: "OAuth2Introspection" was successfully authenticated.
2018-04-11 15:35:22.140 +02:00 [Information] AuthenticationScheme: "OAuth2Introspection" was successfully authenticated.
2018-04-11 15:35:23.233 +02:00 [Information] AuthenticationScheme: "OAuth2Introspection" was successfully authenticated.
2018-04-11 15:35:23.594 +02:00 [Information] AuthenticationScheme: "OAuth2Introspection" was successfully authenticated.
2018-04-11 15:35:24.968 +02:00 [Information] AuthenticationScheme: "OAuth2Introspection" was successfully authenticated.
2018-04-11 15:35:25.258 +02:00 [Information] AuthenticationScheme: "OAuth2Introspection" was successfully authenticated.
2018-04-11 15:35:28.139 +02:00 [Information] AuthenticationScheme: "OAuth2Introspection" was successfully authenticated.
2018-04-11 15:35:30.052 +02:00 [Information] AuthenticationScheme: "OAuth2Introspection" was successfully authenticated.
